<?xml version="1.0" ?>
<robot name="partnet_827c9a85df258dd8faf0b97ff18d3546">
	<link name="base"/>
	<link name="link_0">
		<visual name="frame-2">
			<origin xyz="0 0 0"/>
			<geometry>
				<mesh filename="textured_objs/new-1.obj"/>
			</geometry>
		</visual>
		<collision>
			<origin xyz="0 0 0"/>
			<geometry>
				<mesh filename="textured_objs/new-1.obj"/>
			</geometry>
		</collision>
	</link>
	<joint name="joint_0" type="fixed">
		<origin rpy="1.570796326794897 0 -1.570796326794897" xyz="0 0 0"/>
		<child link="link_0"/>
		<parent link="base"/>
	</joint>
	<link name="link_1">
		<visual name="door_frame-4">
			<origin xyz="0.35772413303425465 -0.8684249999999998 -0.3193075089101187"/>
			<geometry>
				<mesh filename="textured_objs/new-2.obj"/>
			</geometry>
		</visual>
		<visual name="handle-5">
			<origin xyz="0.35772413303425465 -0.8684249999999998 -0.3193075089101187"/>
			<geometry>
				<mesh filename="textured_objs/new-0.obj"/>
			</geometry>
		</visual>
		<collision>
			<origin xyz="0.35772413303425465 -0.8684249999999998 -0.3193075089101187"/>
			<geometry>
				<mesh filename="textured_objs/new-2.obj"/>
			</geometry>
		</collision>
		<collision>
			<origin xyz="0.35772413303425465 -0.8684249999999998 -0.3193075089101187"/>
			<geometry>
				<mesh filename="textured_objs/new-0.obj"/>
			</geometry>
		</collision>
	</link>
	<joint name="joint_1" type="revolute">
		<origin xyz="-0.35772413303425465 0.8684249999999998 0.3193075089101187"/>
		<axis xyz="0 -1 0"/>
		<child link="link_1"/>
		<parent link="link_0"/>
		<limit lower="0.0" upper="3.141592653589793"/>
	</joint>
</robot>
