<?xml version="1.0" encoding="utf-8"?>
<robot name="hand">
    <link name="world"/>
    <joint name="world_joint" type="fixed">
        <parent link="world"/>
        <child link="panda_hand"/>
    </joint>
    <link name="panda_hand">
        <visual>
            <geometry>
                <mesh filename="../franka_description/meshes/visual/hand.dae"/>
            </geometry>
        </visual>
        <collision>
            <geometry>
                <mesh filename="../franka_description/meshes/collision/hand.stl"/>
            </geometry>
        </collision>
        <inertial>
            <origin rpy="0 0 0" xyz="0 0 0"/>
            <mass value="0.5583304799"/>
            <inertia ixx="0.0023394448" ixy="0.0" ixz="0.0" iyy="0.0005782786" iyz="0" izz="0.0021310296"/>
        </inertial>
    </link>
    <link name="panda_leftfinger">
        <visual>
            <geometry>
                <mesh filename="../franka_description/meshes/visual/longer_finger_v2.obj"/>
            </geometry>
        </visual>
        <collision>
            <geometry>
                <mesh filename="../franka_description/meshes/collision/longer_finger_v2.obj"/>
            </geometry>
        </collision>
        <inertial>
            <origin rpy="0 0 0" xyz="0 0 0"/>
            <mass value="0.0140552232"/>
            <inertia ixx="4.20413082650939E-06" ixy="0.0" ixz="0.0" iyy="3.90263687466755E-06" iyz="0"
                     izz="1.33474964199095E-06"/>
        </inertial>
    </link>
    <link name="panda_rightfinger">
        <visual>
            <origin xyz="0 0 0" rpy="0 0 3.1415926"/>
            <geometry>
                <mesh filename="../franka_description/meshes/visual/longer_finger_v2.obj"/>
            </geometry>
        </visual>
        <collision>
            <origin xyz="0 0 0" rpy="0 0 3.1415926"/>
            <geometry>
                <mesh filename="../franka_description/meshes/collision/longer_finger_v2.obj"/>
            </geometry>
        </collision>
        <inertial>
            <origin rpy="0 0 0" xyz="0 0 0"/>
            <mass value="0.0140552232"/>
            <inertia ixx="4.20413082650939E-06" ixy="0.0" ixz="0.0" iyy="3.90263687466755E-06" iyz="0"
                     izz="1.33474964199095E-06"/>
        </inertial>
    </link>
    <joint name="panda_finger_joint1" type="prismatic">
        <parent link="panda_hand"/>
        <child link="panda_leftfinger"/>
        <origin xyz="0 0 0.0584" rpy="0 0 0"/>
        <axis xyz="0 1 0"/>
        <limit effort="20" lower="0.0" upper="0.04" velocity="0.02"/>
    </joint>
    <joint name="panda_finger_joint2" type="prismatic">
        <parent link="panda_hand"/>
        <child link="panda_rightfinger"/>
        <origin xyz="0 0 0.0584" rpy="0 0 0"/>
        <axis xyz="0 -1 0"/>
        <limit effort="20" lower="0.0" upper="0.04" velocity="0.02"/>
        <mimic joint="panda_finger_joint1"/>
    </joint>
    <link name="panda_hand_tcp"/>
    <joint name="panda_hand_tcp_joint" type="fixed">
        <origin rpy="0 0 -1.5707" xyz="0 0 0.1334"/>
        <parent link="panda_hand"/>
        <child link="panda_hand_tcp"/>
    </joint>
    <joint name="joint_finger_tip_left" type="fixed">
        <origin xyz="0.0009 0.021 0.066" rpy="0 0 -1.57"/>
        <parent link="panda_leftfinger"/>
        <child link="finger_left_tip"/>
        <axis xyz="1 0 0"/>
    </joint>
    <link name="finger_left_tip">
        <inertial>
            <mass value="0.1"/>
            <origin xyz="0 0 0"/>
            <inertia ixx="1.0" ixy="0.0" ixz="0.0" iyy="1.0" iyz="0.0" izz="1.0"/>
        </inertial>
        <visual>
            <geometry>
                <mesh filename="../franka_description/meshes/visual/digit_gel_only.STL"/>
            </geometry>
            <material name="white">
                <color rgba="1. 1. 1. 1"/>
            </material>
        </visual>
        <collision>
            <geometry>
                <mesh filename="../franka_description/meshes/visual/digit_gel_only.STL"/>
            </geometry>
        </collision>
    </link>
    <joint name="joint_finger_tip_right" type="fixed">
        <origin xyz="-0.0009 -0.021 0.066" rpy="0 0 1.57"/>
        <parent link="panda_rightfinger"/>
        <child link="finger_right_tip"/>
        <axis xyz="1 0 0"/>
    </joint>
    <link name="finger_right_tip">
        <inertial>
            <mass value="0.1"/>
            <origin xyz="0 0 0"/>
            <inertia ixx="1.0" ixy="0.0" ixz="0.0" iyy="1.0" iyz="0.0" izz="1.0"/>
        </inertial>
        <visual>
            <geometry>
                <mesh filename="../franka_description/meshes/visual/digit_gel_only.STL"/>
            </geometry>
            <material name="white">
                <color rgba="1. 1. 1. 1"/>
            </material>
        </visual>
        <collision>
            <geometry>
                <mesh filename="../franka_description/meshes/visual/digit_gel_only.STL"/>
            </geometry>
        </collision>
    </link>
</robot>
