<?xml version="1.0" ?>
<!-- =================================================================================== -->
<!-- |    This document was autogenerated by xacro from /home/caohaiheng/Projects/ros_ws/src/franka_description/robots/mobile_franka_panda.urdf.xacro | -->
<!-- |    EDITING THIS FILE BY HAND IS NOT RECOMMENDED                                 | -->
<!-- =================================================================================== -->
<robot name="mobile_franka_panda">
    <link name="agv_world_base" />
    <joint name="agv_world_base_joint" type="fixed">
        <origin rpy="0 0 0" xyz="0 0 0.26" />
        <parent link="agv_world_base" />
        <child link="agv_basex" />
    </joint>
    <link name="agv_base">
        <visual>
            <origin xyz="0 0 -0.26" />
            <geometry>
                <mesh filename="../franka_description/meshes/movable_base/base_link.dae" scale="0.8 0.8 0.8" />
            </geometry>
        </visual>
        <collision>
            <origin xyz="0 0 -0.26" />
            <geometry>
                <mesh filename="../franka_description/meshes/movable_base/base_link.dae" scale="0.8 0.8 0.8" />
            </geometry>
        </collision>
        <inertial>
            <mass value="0.1" />
            <origin xyz="0 0 0" rpy="0 0 0" />
            <inertia ixx="0.03" iyy="0.03" izz="0.03" ixy="0.0" ixz="0.0" iyz="0.0" />
        </inertial>
    </link>
    <link name="agv_basex" />
    <link name="agv_basey" />
    <link name="agv_basez" />
    <joint name="agv_base_slider_x" type="prismatic">
        <origin rpy="0 0 0" xyz="0 0 -0.01" />
        <parent link="agv_basex" />
        <child link="agv_basey" />
        <axis xyz="1 0 0" />
        <dynamics damping="10.0" />
        <limit effort="100000" lower="-0.2" upper="0.8" velocity="1" />
    </joint>
    <joint name="agv_base_slider_y" type="prismatic">
        <origin rpy="0 0 0" xyz="0 0 0" />
        <parent link="agv_basey" />
        <child link="agv_basez" />
        <axis xyz="0 1 0" />
        <dynamics damping="10.0" />
        <limit effort="100000" lower="-0.8" upper="0.8" velocity="1" />
    </joint>
    <joint name="agv_base_rotate_z" type="revolute">
        <origin rpy="0 0 0" xyz="0 0 0" />
        <parent link="agv_basez" />
        <child link="agv_base" />
        <axis xyz="0 0 1" />
        <dynamics damping="10.0" />
        <limit effort="100000" lower="-3.1415926" upper="1.5707" velocity="0.5" />
    </joint>
    <link name="agv_pos_link" />
    <joint name="agv_pos_joint" type="fixed">
        <origin rpy="0 0 0" xyz="0 0 -0.26" />
        <parent link="agv_base" />
        <child link="agv_pos_link" />
    </joint>
    <link name="agv_arm_base_link">
        <visual>
            <origin xyz="-0.05 0 0" rpy="0 0 0"/>
            <geometry>
                <box size="0.25 0.2 0.2"/>
            </geometry>
            <material name="gray">
                <color rgba="0.7 0.7 0.7 1"/>
            </material>
        </visual>
        <collision>
            <origin xyz="-0.05 0 0" rpy="0 0 0"/>
            <geometry>
                <box size="0.25 0.2 0.2"/>
            </geometry>
        </collision>
    </link>
    <joint name="agv_arm_base_joint" type="fixed">
        <origin rpy="0 0 0" xyz="0 0 0.13" />
        <parent link="agv_base" />
        <child link="agv_arm_base_link" />
    </joint>
    <joint name="panda_joint_agv_arm_base_link" type="fixed">
        <parent link="agv_arm_base_link" />
        <child link="panda_link0" />
        <origin rpy="0 0 0" xyz="0 0 0.1" />
    </joint>
    <link name="panda_link0">
        <visual>
            <geometry>
                <mesh filename="../franka_description/meshes/visual/link0.dae" />
            </geometry>
        </visual>
        <collision>
            <geometry>
                <mesh filename="../franka_description/meshes/collision/link0.stl" />
            </geometry>
        </collision>
        <inertial>
            <origin rpy="0 0 0" xyz="0 0 0" />
            <mass value="2.8142028896" />
            <inertia ixx="0.0129886979" ixy="0.0" ixz="0.0" iyy="0.0165355284" iyz="0" izz="0.0203311636" />
        </inertial>
    </link>
    <link name="panda_link1">
        <visual>
            <geometry>
                <mesh filename="../franka_description/meshes/visual/link1.dae" />
            </geometry>
        </visual>
        <collision>
            <geometry>
                <mesh filename="../franka_description/meshes/collision/link1.stl" />
            </geometry>
        </collision>
        <inertial>
            <origin rpy="0 0 0" xyz="0 0 0" />
            <mass value="2.3599995791" />
            <inertia ixx="0.0186863903" ixy="0.0" ixz="0.0" iyy="0.0143789874" iyz="0" izz="0.00906812" />
        </inertial>
    </link>
    <joint name="panda_joint1" type="revolute">
        <safety_controller k_position="100.0" k_velocity="40.0" soft_lower_limit="-2.8973" soft_upper_limit="2.8973" />
        <origin rpy="0 0 0" xyz="0 0 0.333" />
        <parent link="panda_link0" />
        <child link="panda_link1" />
        <axis xyz="0 0 1" />
        <limit effort="87" lower="-2.8973" upper="2.8973" velocity="0.5" />
    </joint>
    <link name="panda_link2">
        <visual>
            <geometry>
                <mesh filename="../franka_description/meshes/visual/link2.dae" />
            </geometry>
        </visual>
        <collision>
            <geometry>
                <mesh filename="../franka_description/meshes/collision/link2.stl" />
            </geometry>
        </collision>
        <inertial>
            <origin rpy="0 0 0" xyz="0 0 0" />
            <mass value="2.379518833" />
            <inertia ixx="0.0190388734" ixy="0.0" ixz="0.0" iyy="0.0091429124" iyz="0" izz="0.014697537" />
        </inertial>
    </link>
    <joint name="panda_joint2" type="revolute">
        <safety_controller k_position="100.0" k_velocity="40.0" soft_lower_limit="-1.7628" soft_upper_limit="1.7628" />
        <origin rpy="-1.5707963267948966 0 0" xyz="0 0 0" />
        <parent link="panda_link1" />
        <child link="panda_link2" />
        <axis xyz="0 0 1" />
        <limit effort="87" lower="-1.7628" upper="1.7628" velocity="0.5" />
    </joint>
    <link name="panda_link3">
        <visual>
            <geometry>
                <mesh filename="../franka_description/meshes/visual/link3.dae" />
            </geometry>
        </visual>
        <collision>
            <geometry>
                <mesh filename="../franka_description/meshes/collision/link3.stl" />
            </geometry>
        </collision>
        <inertial>
            <origin rpy="0 0 0" xyz="0 0 0" />
            <mass value="2.6498823337" />
            <inertia ixx="0.0129300178" ixy="0.0" ixz="0.0" iyy="0.0150242121" iyz="0" izz="0.0142734598" />
        </inertial>
    </link>
    <joint name="panda_joint3" type="revolute">
        <safety_controller k_position="100.0" k_velocity="40.0" soft_lower_limit="-2.8973" soft_upper_limit="2.8973" />
        <origin rpy="1.5707963267948966 0 0" xyz="0 -0.316 0" />
        <parent link="panda_link2" />
        <child link="panda_link3" />
        <axis xyz="0 0 1" />
        <limit effort="87" lower="-2.8973" upper="2.8973" velocity="0.5" />
    </joint>
    <link name="panda_link4">
        <visual>
            <geometry>
                <mesh filename="../franka_description/meshes/visual/link4.dae" />
            </geometry>
        </visual>
        <collision>
            <geometry>
                <mesh filename="../franka_description/meshes/collision/link4.stl" />
            </geometry>
        </collision>
        <inertial>
            <origin rpy="0 0 0" xyz="0 0 0" />
            <mass value="2.6948018744" />
            <inertia ixx="0.0133874611" ixy="0.0" ixz="0.0" iyy="0.014514325" iyz="0" izz="0.0155175551" />
        </inertial>
    </link>
    <joint name="panda_joint4" type="revolute">
        <safety_controller k_position="100.0" k_velocity="40.0" soft_lower_limit="-3.0718" soft_upper_limit="-0.0698" />
        <origin rpy="1.5707963267948966 0 0" xyz="0.0825 0 0" />
        <parent link="panda_link3" />
        <child link="panda_link4" />
        <axis xyz="0 0 1" />
        <limit effort="87" lower="-3.0718" upper="-0.0698" velocity="0.5" />
    </joint>
    <link name="panda_link5">
        <visual>
            <geometry>
                <mesh filename="../franka_description/meshes/visual/link5.dae" />
            </geometry>
        </visual>
        <collision>
            <geometry>
                <mesh filename="../franka_description/meshes/collision/link5.stl" />
            </geometry>
        </collision>
        <inertial>
            <origin rpy="0 0 0" xyz="0 0 0" />
            <mass value="2.9812816864" />
            <inertia ixx="0.0325565705" ixy="0.0" ixz="0.0" iyy="0.0270660472" iyz="0" izz="0.0115023375" />
        </inertial>
    </link>
    <joint name="panda_joint5" type="revolute">
        <safety_controller k_position="100.0" k_velocity="40.0" soft_lower_limit="-2.8973" soft_upper_limit="2.8973" />
        <origin rpy="-1.5707963267948966 0 0" xyz="-0.0825 0.384 0" />
        <parent link="panda_link4" />
        <child link="panda_link5" />
        <axis xyz="0 0 1" />
        <limit effort="12" lower="-2.8973" upper="2.8973" velocity="0.5" />
    </joint>
    <link name="panda_link6">
        <visual>
            <geometry>
                <mesh filename="../franka_description/meshes/visual/link6.dae" />
            </geometry>
        </visual>
        <collision>
            <geometry>
                <mesh filename="../franka_description/meshes/collision/link6.stl" />
            </geometry>
        </collision>
        <inertial>
            <origin rpy="0 0 0" xyz="0 0 0" />
            <mass value="1.1285806309" />
            <inertia ixx="0.0026052565" ixy="0.0" ixz="0.0" iyy="0.0039897229" iyz="0" izz="0.0047048591" />
        </inertial>
    </link>
    <joint name="panda_joint6" type="revolute">
        <safety_controller k_position="100.0" k_velocity="40.0" soft_lower_limit="-0.0175" soft_upper_limit="3.7525" />
        <origin rpy="1.5707963267948966 0 0" xyz="0 0 0" />
        <parent link="panda_link5" />
        <child link="panda_link6" />
        <axis xyz="0 0 1" />
        <limit effort="12" lower="-0.0175" upper="3.7525" velocity="0.5" />
    </joint>
    <link name="panda_link7">
        <visual>
            <geometry>
                <mesh filename="../franka_description/meshes/visual/link7.dae" />
            </geometry>
        </visual>
        <collision>
            <geometry>
                <mesh filename="../franka_description/meshes/collision/link7.stl" />
            </geometry>
        </collision>
        <inertial>
            <origin rpy="0 0 0" xyz="0 0 0" />
            <mass value="0.4052912465" />
            <inertia ixx="0.0006316592" ixy="0.0" ixz="0.0" iyy="0.0006319639" iyz="0" izz="0.0010607721" />
        </inertial>
    </link>
    <joint name="panda_joint7" type="revolute">
        <safety_controller k_position="100.0" k_velocity="40.0" soft_lower_limit="-2.8973" soft_upper_limit="2.8973" />
        <origin rpy="1.5707963267948966 0 0" xyz="0.088 0 0" />
        <parent link="panda_link6" />
        <child link="panda_link7" />
        <axis xyz="0 0 1" />
        <limit effort="12" lower="-2.8973" upper="2.8973" velocity="0.5" />
    </joint>
    <link name="panda_link8" />
    <joint name="panda_joint8" type="fixed">
        <origin rpy="0 0 0" xyz="0 0 0.107" />
        <parent link="panda_link7" />
        <child link="panda_link8" />
        <axis xyz="0 0 0" />
    </joint>
    <joint name="panda_hand_joint" type="fixed">
        <parent link="panda_link8" />
        <child link="panda_hand" />
        <origin rpy="0 0 -0.7853981633974483" xyz="0 0 0" />
    </joint>
    <link name="panda_hand">
        <visual>
            <geometry>
                <mesh filename="../franka_description/meshes/visual/hand.dae" />
            </geometry>
        </visual>
        <collision>
            <geometry>
                <mesh filename="../franka_description/meshes/collision/hand.stl" />
            </geometry>
        </collision>
        <inertial>
            <origin rpy="0 0 0" xyz="0 0 0" />
            <mass value="0.5583304799" />
            <inertia ixx="0.0023394448" ixy="0.0" ixz="0.0" iyy="0.0005782786" iyz="0" izz="0.0021310296" />
        </inertial>
    </link>
    <link name="panda_leftfinger">
        <visual>
            <geometry>
                <!-- <mesh filename="../franka_description/meshes/visual/finger.dae" /> -->
                <mesh filename="../franka_description/meshes/visual/longer_finger_v2.obj" />
            </geometry>
        </visual>
        <collision>
            <geometry>
                <mesh filename="../franka_description/meshes/collision/longer_finger_v2.obj" />
            </geometry>
        </collision>
        <inertial>
            <origin rpy="0 0 0" xyz="0 0 0" />
            <mass value="0.0140552232" />
            <inertia ixx="4.20413082650939E-06" ixy="0.0" ixz="0.0" iyy="3.90263687466755E-06" iyz="0" izz="1.33474964199095E-06" />
        </inertial>
    </link>
    <link name="panda_rightfinger">
        <visual>
            <origin rpy="0 0 3.141592653589793" xyz="0 0 0" />
            <geometry>
                <mesh filename="../franka_description/meshes/visual/longer_finger_v2.obj" />
            </geometry>
        </visual>
        <collision>
            <origin rpy="0 0 3.141592653589793" xyz="0 0 0" />
            <geometry>
                <mesh filename="../franka_description/meshes/collision/longer_finger_v2.obj" />
            </geometry>
        </collision>
        <inertial>
            <origin rpy="0 0 0" xyz="0 0 0" />
            <mass value="0.0140552232" />
            <inertia ixx="4.20413082650939E-06" ixy="0.0" ixz="0.0" iyy="3.90263687466755E-06" iyz="0" izz="1.33474964199095E-06" />
        </inertial>
    </link>
    <joint name="panda_finger_joint1" type="prismatic">
        <parent link="panda_hand" />
        <child link="panda_leftfinger" />
        <origin rpy="0 0 0" xyz="0 0 0.0584" />
        <axis xyz="0 1 0" />
        <limit effort="20" lower="0.0" upper="0.04" velocity="0.02" />
    </joint>
    <joint name="panda_finger_joint2" type="prismatic">
        <parent link="panda_hand" />
        <child link="panda_rightfinger" />
        <origin rpy="0 0 0" xyz="0 0 0.0584" />
        <axis xyz="0 -1 0" />
        <limit effort="20" lower="0.0" upper="0.04" velocity="0.02" />
        <mimic joint="panda_finger_joint1" />
    </joint>
    <link name="panda_hand_tcp"/>
    <joint name="panda_hand_tcp_joint" type="fixed">
        <origin rpy="0 0 -1.5707" xyz="0 0 0.1334"/>
        <parent link="panda_hand"/>
        <child link="panda_hand_tcp"/>
    </joint>
    <joint name="joint_finger_tip_left" type="fixed">
        <origin xyz="0.0009 0.021 0.066" rpy="0 0 -1.57"/>
        <parent link="panda_leftfinger"/>
        <child link="finger_left_tip"/>
        <axis xyz="1 0 0"/>
    </joint>
    <link name="finger_left_tip">
        <inertial>
            <mass value="0.001"/>
            <origin xyz="0 0 0"/>
            <inertia ixx="8.045110108333333e-08" ixy="0.0" ixz="0.0" iyy="5.3454052333333326e-08" iyz="0.0" izz="2.9755152750000002e-08"/>
        </inertial>
        <visual>
            <geometry>
                <mesh filename="../franka_description/meshes/visual/digit_gel_only.STL"/>
            </geometry>
            <material name="white">
                <color rgba="1. 1. 1. 1"/>
            </material>
        </visual>
        <collision>
            <geometry>
                <box size="0.004068 0.018453 0.054998"/>
            </geometry>
            <origin xyz="0.018102 0 0.002234"/>
        </collision>
    </link>
    <joint name="joint_finger_tip_right" type="fixed">
        <origin xyz="-0.0009 -0.021 0.066" rpy="0 0 1.57"/>
        <parent link="panda_rightfinger"/>
        <child link="finger_right_tip"/>
        <axis xyz="1 0 0"/>
    </joint>
    <link name="finger_right_tip">
        <inertial>
            <mass value="0.001"/>
            <origin xyz="0 0 0"/>
            <inertia ixx="8.045110108333333e-08" ixy="0.0" ixz="0.0" iyy="5.3454052333333326e-08" iyz="0.0" izz="2.9755152750000002e-08"/>
        </inertial>
        <visual>
            <geometry>
                <mesh filename="../franka_description/meshes/visual/digit_gel_only.STL"/>
            </geometry>
            <material name="white">
                <color rgba="1. 1. 1. 1"/>
            </material>
        </visual>
        <collision>
            <geometry>
                <box size="0.004068 0.018453 0.054998"/>
            </geometry>
            <origin xyz="0.018102 0 0.002234"/>
        </collision>
    </link>
    <joint name="camera_stand_joint" type="fixed">
        <origin xyz="0 -0.15 0.6" rpy="0 0 0"/>
        <parent link="agv_base"/>
        <child link="camera_stand_link"/>
    </joint>
    <link name="camera_stand_link">
        <visual>
            <origin xyz="-0.01 -0.15 0"/>
            <geometry>
                <box size="0.02 0.02 1.2"/>
            </geometry>
            <material name="gray">
                <color rgba="0.7 0.7 0.7 1"/>
            </material>
        </visual>
        <collision>
            <origin xyz="-0.01 -0.15 0"/>
            <geometry>
                <box size="0.02 0.02 1.2"/>
            </geometry>
        </collision>
        <visual>
            <origin xyz="-0.01 -0.075 -0.6"/>
            <geometry>
                <box size="0.02 0.15 0.02"/>
            </geometry>
            <material name="gray">
                <color rgba="0.7 0.7 0.7 1"/>
            </material>
        </visual>
        <collision>
            <origin xyz="-0.01 -0.075 -0.6"/>
            <geometry>
                <box size="0.02 0.15 0.02"/>
            </geometry>
        </collision>
    </link>
    <joint name="base_camera_joint" type="fixed">
        <parent link="agv_base"/>
        <child link="base_camera_link"/>
        <origin xyz="0 -0.3 1.2" rpy="0 0.43633 0"/>
    </joint>
    <link name="base_camera_link">
        <visual>
            <origin xyz="-0.01 0 0"/>
            <geometry>
                <box size="0.02 0.05 0.02"/>
            </geometry>
            <material name="gray">
                <color rgba="0.7 0.7 0.7 1"/>
            </material>
        </visual>
        <collision>
            <origin xyz="-0.01 0 0"/>
            <geometry>
                <box size="0.02 0.05 0.02"/>
            </geometry>
        </collision>
    </link>
    <joint name="gripper_camera_joint" type="fixed">
        <parent link="panda_hand"/>
        <child link="gripper_camera_link"/>
        <origin xyz="0.05 0 0.05" rpy="3.1415926 -1.5707963 0"/>
    </joint>
    <link name="gripper_camera_link">
        <visual>
            <origin xyz="-0.01 0 0"/>
            <geometry>
                <box size="0.02 0.05 0.02"/>
            </geometry>
            <material name="gray">
                <color rgba="0.7 0.7 0.7 1"/>
            </material>
        </visual>
        <collision>
            <origin xyz="-0.01 0 0"/>
            <geometry>
                <box size="0.02 0.05 0.02"/>
            </geometry>
        </collision>
    </link>
</robot>

